<?xml version="1.0" encoding="utf-8"?>
<!-- This URDF was automatically created by SolidWorks to URDF Exporter! Originally created by Stephen Brawner (brawner@gmail.com) 
     Commit Version: 1.5.1-0-g916b5db  Build Version: 1.5.7152.31018
     For more information, please see http://wiki.ros.org/sw_urdf_exporter -->
<robot
  name="brazo5_nomesh">
  <link
    name="Base_link">
    <inertial>
      <origin
        xyz="0.080296 0.155 0.21875"
        rpy="0 0 0" />
      <mass
        value="4.9779" />
      <inertia
        ixx="0.029645"
        ixy="-9.2377E-06"
        ixz="-1.1656E-08"
        iyy="0.027618"
        iyz="-4.9899E-05"
        izz="0.029622" />
    </inertial>
    <visual>
      <origin
        xyz="0 0 0"
        rpy="0 0 0" />
      <geometry>
        <mesh
          filename="package://brazo5_nomesh/meshes/Base_link.STL" />
      </geometry>
      <material
        name="">
        <color
          rgba="0.79216 0.81961 0.93333 1" />
      </material>
    </visual>
    <collision>
      <origin
        xyz="0 0 0"
        rpy="0 0 0" />
      <geometry>
        <mesh
          filename="package://brazo5_nomesh/meshes/Base_link.STL" />
      </geometry>
    </collision>
  </link>
  <link
    name="Link_1">
    <inertial>
      <origin
        xyz="6.9389E-18 0.10821 -1.3834E-07"
        rpy="0 0 0" />
      <mass
        value="2.2449" />
      <inertia
        ixx="0.014264"
        ixy="2.3062E-18"
        ixz="-4.8688E-07"
        iyy="0.0048827"
        iyz="-3.2054E-08"
        izz="0.011413" />
    </inertial>
    <visual>
      <origin
        xyz="0 0 0"
        rpy="0 0 0" />
      <geometry>
        <mesh
          filename="package://brazo5_nomesh/meshes/Link_1.STL" />
      </geometry>
      <material
        name="">
        <color
          rgba="0.79216 0.81961 0.93333 1" />
      </material>
    </visual>
    <collision>
      <origin
        xyz="0 0 0"
        rpy="0 0 0" />
      <geometry>
        <mesh
          filename="package://brazo5_nomesh/meshes/Link_1.STL" />
      </geometry>
    </collision>
  </link>
  <joint
    name="joint_1"
    type="revolute">
    <origin
      xyz="0.080329 -0.21885 0.24416"
      rpy="1.5708 0 0.085579" />
    <parent
      link="Base_link" />
    <child
      link="Link_1" />
    <axis
      xyz="0 1 0" />
    <limit
      lower="0"
      upper="3.14"
      effort="30"
      velocity="1" />
  </joint>
  <link
    name="Link_2">
    <inertial>
      <origin
        xyz="8.3561E-05 0.064104 -9.1491E-06"
        rpy="0 0 0" />
      <mass
        value="2.0309" />
      <inertia
        ixx="0.0095089"
        ixy="-6.2024E-08"
        ixz="2.1158E-08"
        iyy="0.0089388"
        iyz="9.505E-08"
        izz="0.011063" />
    </inertial>
    <visual>
      <origin
        xyz="0 0 0"
        rpy="0 0 0" />
      <geometry>
        <mesh
          filename="package://brazo5_nomesh/meshes/Link_2.STL" />
      </geometry>
      <material
        name="">
        <color
          rgba="0.79216 0.81961 0.93333 1" />
      </material>
    </visual>
    <collision>
      <origin
        xyz="0 0 0"
        rpy="0 0 0" />
      <geometry>
        <mesh
          filename="package://brazo5_nomesh/meshes/Link_2.STL" />
      </geometry>
    </collision>
  </link>
  <joint
    name="joint_2"
    type="revolute">
    <origin
      xyz="0 0.19199 0"
      rpy="0.0089945 0 0" />
    <parent
      link="Link_1" />
    <child
      link="Link_2" />
    <axis
      xyz="1 0 0" />
    <limit
      lower="0"
      upper="2.1"
      effort="30"
      velocity="1" />
  </joint>
  <link
    name="Link_3">
    <inertial>
      <origin
        xyz="1.6463E-09 0.10977 -1.4195E-07"
        rpy="0 0 0" />
      <mass
        value="2.2449" />
      <inertia
        ixx="0.014264"
        ixy="-3.3726E-10"
        ixz="-4.8697E-07"
        iyy="0.0048827"
        iyz="-3.1579E-08"
        izz="0.011413" />
    </inertial>
    <visual>
      <origin
        xyz="0 0 0"
        rpy="0 0 0" />
      <geometry>
        <mesh
          filename="package://brazo5_nomesh/meshes/Link_3.STL" />
      </geometry>
      <material
        name="">
        <color
          rgba="0.79216 0.81961 0.93333 1" />
      </material>
    </visual>
    <collision>
      <origin
        xyz="0 0 0"
        rpy="0 0 0" />
      <geometry>
        <mesh
          filename="package://brazo5_nomesh/meshes/Link_3.STL" />
      </geometry>
    </collision>
  </link>
  <joint
    name="joint_3"
    type="revolute">
    <origin
      xyz="8.3666E-05 0.13929 0"
      rpy="0 0.021739 0" />
    <parent
      link="Link_2" />
    <child
      link="Link_3" />
    <axis
      xyz="0 1 0" />
    <limit
      lower="0"
      upper="3.14"
      effort="30"
      velocity="1" />
  </joint>
  <link
    name="Link_4">
    <inertial>
      <origin
        xyz="8.3564E-05 0.064104 -9.1303E-06"
        rpy="0 0 0" />
      <mass
        value="2.0309" />
      <inertia
        ixx="0.0095089"
        ixy="-6.2294E-08"
        ixz="2.117E-08"
        iyy="0.0089388"
        iyz="9.6477E-08"
        izz="0.011063" />
    </inertial>
    <visual>
      <origin
        xyz="0 0 0"
        rpy="0 0 0" />
      <geometry>
        <mesh
          filename="package://brazo5_nomesh/meshes/Link_4.STL" />
      </geometry>
      <material
        name="">
        <color
          rgba="0.79216 0.81961 0.93333 1" />
      </material>
    </visual>
    <collision>
      <origin
        xyz="0 0 0"
        rpy="0 0 0" />
      <geometry>
        <mesh
          filename="package://brazo5_nomesh/meshes/Link_4.STL" />
      </geometry>
    </collision>
  </link>
  <joint
    name="joint_4"
    type="revolute">
    <origin
      xyz="0 0.19355 0"
      rpy="-0.015469 0 0" />
    <parent
      link="Link_3" />
    <child
      link="Link_4" />
    <axis
      xyz="1 0 0" />
    <limit
      lower="0"
      upper="2"
      effort="30"
      velocity="1" />
  </joint>
  <link
    name="Link_5">
    <inertial>
      <origin
        xyz="-1.3685E-09 0.10813 -1.3516E-07"
        rpy="0 0 0" />
      <mass
        value="2.2449" />
      <inertia
        ixx="0.014264"
        ixy="2.7614E-10"
        ixz="-4.8695E-07"
        iyy="0.0048827"
        iyz="-3.2503E-08"
        izz="0.011413" />
    </inertial>
    <visual>
      <origin
        xyz="0 0 0"
        rpy="0 0 0" />
      <geometry>
        <mesh
          filename="package://brazo5_nomesh/meshes/Link_5.STL" />
      </geometry>
      <material
        name="">
        <color
          rgba="0.79216 0.81961 0.93333 1" />
      </material>
    </visual>
    <collision>
      <origin
        xyz="0 0 0"
        rpy="0 0 0" />
      <geometry>
        <mesh
          filename="package://brazo5_nomesh/meshes/Link_5.STL" />
      </geometry>
    </collision>
  </link>
  <joint
    name="joint_5"
    type="revolute">
    <origin
      xyz="8.3666E-05 0.14093 0"
      rpy="0 -0.029656 0" />
    <parent
      link="Link_4" />
    <child
      link="Link_5" />
    <axis
      xyz="0 1 0" />
    <limit
      lower="0"
      upper="3.14"
      effort="30"
      velocity="1" />
  </joint>
  <link
    name="Link_6">
    <inertial>
      <origin
        xyz="8.384E-05 0.082855 -4.5611E-06"
        rpy="0 0 0" />
      <mass
        value="2.4359" />
      <inertia
        ixx="0.010186"
        ixy="-1.1553E-07"
        ixz="1.9654E-05"
        iyy="0.0095612"
        iyz="-5.5533E-07"
        izz="0.011978" />
    </inertial>
    <visual>
      <origin
        xyz="0 0 0"
        rpy="0 0 0" />
      <geometry>
        <mesh
          filename="package://brazo5_nomesh/meshes/Link_6.STL" />
      </geometry>
      <material
        name="">
        <color
          rgba="0.79216 0.81961 0.93333 1" />
      </material>
    </visual>
    <collision>
      <origin
        xyz="0 0 0"
        rpy="0 0 0" />
      <geometry>
        <mesh
          filename="package://brazo5_nomesh/meshes/Link_6.STL" />
      </geometry>
    </collision>
  </link>
  <joint
    name="joint_6"
    type="revolute">
    <origin
      xyz="0 0.19191 0"
      rpy="3.1238 0 -3.1416" />
    <parent
      link="Link_5" />
    <child
      link="Link_6" />
    <axis
      xyz="1 0 0" />
    <limit
      lower="0"
      upper="2"
      effort="30"
      velocity="1" />
  </joint>
</robot>